Workbook

Sheet COVER
A2: ARGENTINA MINING SECTOR │ Generic CRM Demand Forecasting & Strategy Model
A3: Parameterizable for any Critical Raw Material · Methodology adapted from EU Copper Sector Analysis (2026)
A5: MODEL OVERVIEW
A6: Purpose | D6: Forecast global demand and market opportunities for Critical Raw Materials (CRMs) and design an optimal supply strategy for Argentina's mining sector.
A7: Methodology | D7: 3-scenario demand forecast (HIGH / REALISTIC / LOW) × supply potential assessment under CONSERVATIVE / BASE / MAXIMUM assumptions. Adapted from the EU Copper Sector Analysis (2026) framework.
A8: CRM Coverage | D8: Generic model: change the CRM name and base parameters in the PARAMETERS sheet to apply the model to Copper, Lithium, Nickel, Cobalt, Rare Earths or any other CRM. Default values are pre-populated for Copper.
A9: Argentina Context | D9: Argentina holds world-class reserves across all major CRMs — copper (San Juan, Catamarca, Salta), lithium (Lithium Triangle), nickel/cobalt (Neuquén) — and is positioning as a key supplier for global energy transition demand.
A11: NAVIGATION — Click a sheet name to go directly
A12: PARAMETERS | D12: All model inputs: CRM parameters, scenario assumptions, Argentina project pipeline
A13: DEMAND_FORECAST | D13: Global CRM demand projection 2025–2040 under HIGH / REALISTIC / LOW scenarios
A14: ARGENTINA_SUPPLY | D14: Argentina's supply potential 2025–2040 under CONSERVATIVE / BASE / MAXIMUM scenarios
A15: MARKET_GAP | D15: Global supply-demand gap and Argentina's addressable market opportunity
A16: AR_OPPORTUNITY | D16: Revenue, CAPEX and economic impact analysis for Argentina
A17: COUNTRY_SCORING | D17: Project and country attractiveness scoring: Argentina vs. key competitors
A18: PATHWAYS | D18: Three strategic pathways for Argentina's mining sector development
A19: RECOMMENDATIONS | D19: Actionable guidelines for optimal strategy implementation
A20: DASHBOARD | D20: Executive summary: key charts and KPIs
A22: CONFIDENTIAL · This model is based on publicly available data supplemented by the proprietary EU Copper Sector Analysis (2026). Blue cells = hardcoded inputs (user may modify). Black cells = formulas (do not overwrite). Green cells = cross-sheet references.

Sheet PARAMETERS
A1: PARAMETERS — All Model Inputs (Blue cells = inputs you may change)
A3: A. MODEL PARAMETERS
A4: CRM Name | B4: Copper | C4: Name of the Critical Raw Material (e.g. Copper, Lithium, Nickel, Cobalt)
A5: Base Year | B5: 2025 | C5: First year of analysis (historical baseline)
A6: Forecast End Year | B6: 2040 | C6: Last year of the forecast horizon
A7: Unit of Demand | B7: kt Cu-eq | C7: Unit used throughout the model (e.g. kt Cu-eq, kt LCE)
A8: Reference Region | B8: Global | C8: Geography of demand analysis (Global / Regional)
A9: Argentina Context | B9: Producer / Exporter | C9: Argentina's role in the CRM value chain
A11: B. GLOBAL BASELINE DEMAND (2025, kt) — 'Focus' and 'Non-Focus' applications
A12: Application | C12: 2025 Demand (kt) | D12: % of Total | E12: Focus? | F12: Primary Driver
A13: Power Grid & Transmission | C13: 5500 | D13: =IF(C$21>0,C13/C$21,0) -> 0.21153846 | E13: Yes | F13: Decarbonisation / Grid expansion
A14: Electric Vehicles (EVs) | C14: 2800 | D14: =IF(C$21>0,C14/C$21,0) -> 0.10769231 | E14: Yes | F14: Decarbonisation / EV adoption
A15: Renewable Energy (Solar & Wind) | C15: 1800 | D15: =IF(C$21>0,C15/C$21,0) -> 0.069230769 | E15: Yes | F15: Decarbonisation / RES expansion
A16: Data Centers & Digitalization | C16: 1200 | D16: =IF(C$21>0,C16/C$21,0) -> 0.046153846 | E16: Yes | F16: Digitalization
A17: Defense & Aerospace | C17: 500 | D17: =IF(C$21>0,C17/C$21,0) -> 0.019230769 | E17: Yes | F17: Defense spend re-armament
A18: Buildings & Construction | C18: 7200 | D18: =IF(C$21>0,C18/C$21,0) -> 0.27692308 | E18: No | F18: GDP / Urbanization
A19: Industrial Equipment & Machinery | C19: 4000 | D19: =IF(C$21>0,C19/C$21,0) -> 0.15384615 | E19: No | F19: GDP / Manufacturing
A20: Appliances, Electronics & Other | C20: 3000 | D20: =IF(C$21>0,C20/C$21,0) -> 0.11538462 | E20: No | F20: GDP / Consumer demand
A21: TOTAL | C21: =SUM(C13:C20) -> 26000 | D21: =SUM(D13:D20) -> 1 | F21: Global consumption benchmark: ~26,000 kt for Copper (2025 ICSG)
A23: C. DEMAND SCENARIO ASSUMPTIONS — CAGR by Application (2025–2040)
A24: Application | C24: HIGH Scenario CAGR | D24: REALISTIC Scenario CAGR | E24: LOW Scenario CAGR | F24: Notes / Rationale
A25: Power Grid & Transmission | C25: 0.05 | D25: 0.035 | E25: 0.018 | F25: High: rapid net-zero grid build-out; Low: slow policy implementation
A26: Electric Vehicles (EVs) | C26: 0.09 | D26: 0.065 | E26: 0.04 | F26: High: 90% EV share by 2040; Realistic: 80%; Low: 55%
A27: Renewable Energy (Solar & Wind) | C27: 0.08 | D27: 0.06 | E27: 0.038 | F27: Driven by installed capacity additions (GW)
A28: Data Centers & Digitalization | C28: 0.065 | D28: 0.05 | E28: 0.03 | F28: AI & cloud infrastructure expansion globally
A29: Defense & Aerospace | C29: 0.06 | D29: 0.04 | E29: 0.025 | F29: Global re-armament wave; Realistic: 3% GDP NATO+ by 2030
A30: Buildings & Construction | C30: 0.015 | D30: 0.008 | E30: 0.002 | F30: GDP-correlated; partially offset by material efficiency gains
A31: Industrial Equipment & Machinery | C31: 0.02 | D31: 0.012 | E31: 0.005 | F31: Manufacturing re-shoring supports mid scenario
A32: Appliances, Electronics & Other | C32: 0.015 | D32: 0.01 | E32: 0.003 | F32: Steady but moderate; partial substitution risk
A33: Source: Adapted from EU Copper Sector Analysis (2026); IEA WEO 2025; ICSG
A35: D. ARGENTINA MINING PROJECT PIPELINE (Copper default — replace for other CRMs)
A36: Project / Mine | B36: Province | C36: Type | D36: Status | E36: Annual Capacity (kt) | F36: Mine Life (years) | G36: Ore Grade (%) | H36: Start of Production | I36: CONSERVATIVE Scenario? | J36: BASE Scenario? | K36: MAX Scenario?
A37: Bajo de la Alumbrera* | B37: Catamarca | C37: Operating/Wind-down | D37: Operating | E37: 50 | F37: 30 | G37: 0.4 | H37: 2025 | I37: Y | J37: Y | K37: Y
A38: MARA (Agua Rica) | B38: Catamarca | C38: Greenfield | D38: Development | E38: 200 | F38: 28 | G38: 0.49 | H38: 2029 | I38: N | J38: Y | K38: Y
A39: Josemaría | B39: San Juan | C39: Greenfield | D39: Development | E39: 150 | F39: 19 | G39: 0.32 | H39: 2031 | I39: N | J39: Y | K39: Y
A40: El Pachón | B40: San Juan | C40: Greenfield | D40: Development | E40: 200 | F40: 25 | G40: 0.57 | H40: 2032 | I40: N | J40: N | K40: Y
A41: Los Azules | B41: San Juan | C41: Greenfield | D41: Development | E41: 200 | F41: 27 | G41: 0.38 | H41: 2033 | I41: N | J41: N | K41: Y
A42: Taca Taca | B42: Salta | C42: Greenfield | D42: Exploration | E42: 170 | F42: 20 | G42: 0.4 | H42: 2033 | I42: N | J42: N | K42: Y
A43: Altar | B43: San Juan | C43: Greenfield | D43: Exploration | E43: 100 | F43: 22 | G43: 0.33 | H43: 2035 | I43: N | J43: N | K43: Y
A44: San Jorge | B44: Mendoza | C44: Brownfield | D44: Permitting | E44: 70 | F44: 16 | G44: 0.52 | H44: 2034 | I44: N | J44: N | K44: Y
...

Sheet DEMAND_FORECAST
A1: DEMAND FORECAST — Global CRM Demand 2025–2040 by Scenario (kt)
A3: Application / Scenario | B3: App # | C3: 2025 | D3: 2026 | E3: 2027 | F3: 2028 | G3: 2029 | H3: 2030 | I3: 2031 | J3: 2032 | K3: 2033 | L3: 2034 | M3: 2035 | N3: 2036 | O3: 2037 | P3: 2038 | Q3: 2039 | R3: 2040 | S3: CAGR 25-30 | T3: CAGR 31-35 | U3: CAGR 36-40 | V3: 2040 vs 2025
A4: Source: PARAMETERS!B, row-by-row CAGR applied per scenario. Applications 1–5 = 'Focus'; 6–8 = 'Non-Focus'.
A5: HIGH SCENARIO
A6: Power Grid & Transmission | B6: 1 | C6: =PARAMETERS!$C$13 -> 5500 | D6: =C6*(1+PARAMETERS!$C$25) -> 5775 | E6: =D6*(1+PARAMETERS!$C$25) -> 6063.75 | F6: =E6*(1+PARAMETERS!$C$25) -> 6366.9375 | G6: =F6*(1+PARAMETERS!$C$25) -> 6685.2844 | H6: =G6*(1+PARAMETERS!$C$25) -> 7019.5486 | I6: =H6*(1+PARAMETERS!$C$25) -> 7370.526 | J6: =I6*(1+PARAMETERS!$C$25) -> 7739.0523 | K6: =J6*(1+PARAMETERS!$C$25) -> 8126.0049 | ... R6: =Q6*(1+PARAMETERS!$C$25) -> 11434.105 | S6: =IF(C6>0,(H6/C6)^(1/5)-1,0) -> 0.05 | T6: =IF(H6>0,(M6/H6)^(1/5)-1,0) -> 0.05 | U6: =IF(M6>0,(R6/M6)^(1/5)-1,0) -> 0.05 | V6: =IF(C6>0,R6/C6,0) -> 2.0789282
A7: Electric Vehicles (EVs) | B7: 2 | C7: =PARAMETERS!$C$14 -> 2800 | D7: =C7*(1+PARAMETERS!$C$26) -> 3052 | E7: =D7*(1+PARAMETERS!$C$26) -> 3326.68 | F7: =E7*(1+PARAMETERS!$C$26) -> 3626.0812 | G7: =F7*(1+PARAMETERS!$C$26) -> 3952.4285 | H7: =G7*(1+PARAMETERS!$C$26) -> 4308.1471 | I7: =H7*(1+PARAMETERS!$C$26) -> 4695.8803 | J7: =I7*(1+PARAMETERS!$C$26) -> 5118.5095 | K7: =J7*(1+PARAMETERS!$C$26) -> 5579.1754 | ... R7: =Q7*(1+PARAMETERS!$C$26) -> 10198.951 | S7: =IF(C7>0,(H7/C7)^(1/5)-1,0) -> 0.09 | T7: =IF(H7>0,(M7/H7)^(1/5)-1,0) -> 0.09 | U7: =IF(M7>0,(R7/M7)^(1/5)-1,0) -> 0.09 | V7: =IF(C7>0,R7/C7,0) -> 3.6424825
A8: Renewable Energy (Solar & Wind) | B8: 3 | C8: =PARAMETERS!$C$15 -> 1800 | D8: =C8*(1+PARAMETERS!$C$27) -> 1944 | E8: =D8*(1+PARAMETERS!$C$27) -> 2099.52 | F8: =E8*(1+PARAMETERS!$C$27) -> 2267.4816 | G8: =F8*(1+PARAMETERS!$C$27) -> 2448.8801 | H8: =G8*(1+PARAMETERS!$C$27) -> 2644.7905 | I8: =H8*(1+PARAMETERS!$C$27) -> 2856.3738 | J8: =I8*(1+PARAMETERS!$C$27) -> 3084.8837 | K8: =J8*(1+PARAMETERS!$C$27) -> 3331.6744 | ... R8: =Q8*(1+PARAMETERS!$C$27) -> 5709.9044 | S8: =IF(C8>0,(H8/C8)^(1/5)-1,0) -> 0.08 | T8: =IF(H8>0,(M8/H8)^(1/5)-1,0) -> 0.08 | U8: =IF(M8>0,(R8/M8)^(1/5)-1,0) -> 0.08 | V8: =IF(C8>0,R8/C8,0) -> 3.1721691
A9: Data Centers & Digitalization | B9: 4 | C9: =PARAMETERS!$C$16 -> 1200 | D9: =C9*(1+PARAMETERS!$C$28) -> 1278 | E9: =D9*(1+PARAMETERS!$C$28) -> 1361.07 | F9: =E9*(1+PARAMETERS!$C$28) -> 1449.5395 | G9: =F9*(1+PARAMETERS!$C$28) -> 1543.7596 | H9: =G9*(1+PARAMETERS!$C$28) -> 1644.104 | I9: =H9*(1+PARAMETERS!$C$28) -> 1750.9708 | J9: =I9*(1+PARAMETERS!$C$28) -> 1864.7839 | K9: =J9*(1+PARAMETERS!$C$28) -> 1985.9948 | ... R9: =Q9*(1+PARAMETERS!$C$28) -> 3086.2092 | S9: =IF(C9>0,(H9/C9)^(1/5)-1,0) -> 0.065 | T9: =IF(H9>0,(M9/H9)^(1/5)-1,0) -> 0.065 | U9: =IF(M9>0,(R9/M9)^(1/5)-1,0) -> 0.065 | V9: =IF(C9>0,R9/C9,0) -> 2.571841
A10: Defense & Aerospace | B10: 5 | C10: =PARAMETERS!$C$17 -> 500 | D10: =C10*(1+PARAMETERS!$C$29) -> 530 | E10: =D10*(1+PARAMETERS!$C$29) -> 561.8 | F10: =E10*(1+PARAMETERS!$C$29) -> 595.508 | G10: =F10*(1+PARAMETERS!$C$29) -> 631.23848 | H10: =G10*(1+PARAMETERS!$C$29) -> 669.11279 | I10: =H10*(1+PARAMETERS!$C$29) -> 709.25956 | J10: =I10*(1+PARAMETERS!$C$29) -> 751.81513 | K10: =J10*(1+PARAMETERS!$C$29) -> 796.92404 | ... R10: =Q10*(1+PARAMETERS!$C$29) -> 1198.2791 | S10: =IF(C10>0,(H10/C10)^(1/5)-1,0) -> 0.06 | T10: =IF(H10>0,(M10/H10)^(1/5)-1,0) -> 0.06 | U10: =IF(M10>0,(R10/M10)^(1/5)-1,0) -> 0.06 | V10: =IF(C10>0,R10/C10,0) -> 2.3965582
A11: Buildings & Construction | B11: 6 | C11: =PARAMETERS!$C$18 -> 7200 | D11: =C11*(1+PARAMETERS!$C$30) -> 7308 | E11: =D11*(1+PARAMETERS!$C$30) -> 7417.62 | F11: =E11*(1+PARAMETERS!$C$30) -> 7528.8843 | G11: =F11*(1+PARAMETERS!$C$30) -> 7641.8176 | H11: =G11*(1+PARAMETERS!$C$30) -> 7756.4448 | I11: =H11*(1+PARAMETERS!$C$30) -> 7872.7915 | J11: =I11*(1+PARAMETERS!$C$30) -> 7990.8834 | K11: =J11*(1+PARAMETERS!$C$30) -> 8110.7466 | ... R11: =Q11*(1+PARAMETERS!$C$30) -> 9001.6709 | S11: =IF(C11>0,(H11/C11)^(1/5)-1,0) -> 0.015 | T11: =IF(H11>0,(M11/H11)^(1/5)-1,0) -> 0.015 | U11: =IF(M11>0,(R11/M11)^(1/5)-1,0) -> 0.015 | V11: =IF(C11>0,R11/C11,0) -> 1.2502321
A12: Industrial Equipment & Machinery | B12: 7 | C12: =PARAMETERS!$C$19 -> 4000 | D12: =C12*(1+PARAMETERS!$C$31) -> 4080 | E12: =D12*(1+PARAMETERS!$C$31) -> 4161.6 | F12: =E12*(1+PARAMETERS!$C$31) -> 4244.832 | G12: =F12*(1+PARAMETERS!$C$31) -> 4329.7286 | H12: =G12*(1+PARAMETERS!$C$31) -> 4416.3232 | I12: =H12*(1+PARAMETERS!$C$31) -> 4504.6497 | J12: =I12*(1+PARAMETERS!$C$31) -> 4594.7427 | K12: =J12*(1+PARAMETERS!$C$31) -> 4686.6375 | ... R12: =Q12*(1+PARAMETERS!$C$31) -> 5383.4734 | S12: =IF(C12>0,(H12/C12)^(1/5)-1,0) -> 0.02 | T12: =IF(H12>0,(M12/H12)^(1/5)-1,0) -> 0.02 | U12: =IF(M12>0,(R12/M12)^(1/5)-1,0) -> 0.02 | V12: =IF(C12>0,R12/C12,0) -> 1.3458683
A13: Appliances, Electronics & Other | B13: 8 | C13: =PARAMETERS!$C$20 -> 3000 | D13: =C13*(1+PARAMETERS!$C$32) -> 3045 | E13: =D13*(1+PARAMETERS!$C$32) -> 3090.675 | F13: =E13*(1+PARAMETERS!$C$32) -> 3137.0351 | G13: =F13*(1+PARAMETERS!$C$32) -> 3184.0907 | H13: =G13*(1+PARAMETERS!$C$32) -> 3231.852 | I13: =H13*(1+PARAMETERS!$C$32) -> 3280.3298 | J13: =I13*(1+PARAMETERS!$C$32) -> 3329.5347 | K13: =J13*(1+PARAMETERS!$C$32) -> 3379.4778 | ... R13: =Q13*(1+PARAMETERS!$C$32) -> 3750.6962 | S13: =IF(C13>0,(H13/C13)^(1/5)-1,0) -> 0.015 | T13: =IF(H13>0,(M13/H13)^(1/5)-1,0) -> 0.015 | U13: =IF(M13>0,(R13/M13)^(1/5)-1,0) -> 0.015 | V13: =IF(C13>0,R13/C13,0) -> 1.2502321
A14: TOTAL — HIGH SCENARIO | C14: =SUM(C6:C13) -> 26000 | D14: =SUM(D6:D13) -> 27012 | E14: =SUM(E6:E13) -> 28082.715 | F14: =SUM(F6:F13) -> 29216.299 | G14: =SUM(G6:G13) -> 30417.228 | H14: =SUM(H6:H13) -> 31690.323 | I14: =SUM(I6:I13) -> 33040.781 | J14: =SUM(J6:J13) -> 34474.205 | ... R14: =SUM(R6:R13) -> 49763.289 | S14: =IF(C14>0,(H14/C14)^(1/5)-1,0) -> 0.040376811 | T14: =IF(H14>0,(M14/H14)^(1/5)-1,0) -> 0.044168744 | U14: =IF(M14>0,(R14/M14)^(1/5)-1,0) -> 0.048155682 | V14: =IF(C14>0,R14/C14,0) -> 1.9139727
A16: REALISTIC SCENARIO
A17: Power Grid & Transmission | B17: 1 | C17: =PARAMETERS!$C$13 -> 5500 | D17: =C17*(1+PARAMETERS!$D$25) -> 5692.5 | E17: =D17*(1+PARAMETERS!$D$25) -> 5891.7375 | F17: =E17*(1+PARAMETERS!$D$25) -> 6097.9483 | G17: =F17*(1+PARAMETERS!$D$25) -> 6311.3765 | H17: =G17*(1+PARAMETERS!$D$25) -> 6532.2747 | I17: =H17*(1+PARAMETERS!$D$25) -> 6760.9043 | J17: =I17*(1+PARAMETERS!$D$25) -> 6997.5359 | K17: =J17*(1+PARAMETERS!$D$25) -> 7242.4497 | ... R17: =Q17*(1+PARAMETERS!$D$25) -> 9214.4186 | S17: =IF(C17>0,(H17/C17)^(1/5)-1,0) -> 0.035 | T17: =IF(H17>0,(M17/H17)^(1/5)-1,0) -> 0.035 | U17: =IF(M17>0,(R17/M17)^(1/5)-1,0) -> 0.035 | V17: =IF(C17>0,R17/C17,0) -> 1.6753488
A18: Electric Vehicles (EVs) | B18: 2 | C18: =PARAMETERS!$C$14 -> 2800 | D18: =C18*(1+PARAMETERS!$D$26) -> 2982 | E18: =D18*(1+PARAMETERS!$D$26) -> 3175.83 | F18: =E18*(1+PARAMETERS!$D$26) -> 3382.2589 | G18: =F18*(1+PARAMETERS!$D$26) -> 3602.1058 | H18: =G18*(1+PARAMETERS!$D$26) -> 3836.2427 | I18: =H18*(1+PARAMETERS!$D$26) -> 4085.5984 | J18: =I18*(1+PARAMETERS!$D$26) -> 4351.1623 | K18: =J18*(1+PARAMETERS!$D$26) -> 4633.9879 | ... R18: =Q18*(1+PARAMETERS!$D$26) -> 7201.1548 | S18: =IF(C18>0,(H18/C18)^(1/5)-1,0) -> 0.065 | T18: =IF(H18>0,(M18/H18)^(1/5)-1,0) -> 0.065 | U18: =IF(M18>0,(R18/M18)^(1/5)-1,0) -> 0.065 | V18: =IF(C18>0,R18/C18,0) -> 2.571841
A19: Renewable Energy (Solar & Wind) | B19: 3 | C19: =PARAMETERS!$C$15 -> 1800 | D19: =C19*(1+PARAMETERS!$D$27) -> 1908 | E19: =D19*(1+PARAMETERS!$D$27) -> 2022.48 | F19: =E19*(1+PARAMETERS!$D$27) -> 2143.8288 | G19: =F19*(1+PARAMETERS!$D$27) -> 2272.4585 | H19: =G19*(1+PARAMETERS!$D$27) -> 2408.806 | I19: =H19*(1+PARAMETERS!$D$27) -> 2553.3344 | J19: =I19*(1+PARAMETERS!$D$27) -> 2706.5345 | K19: =J19*(1+PARAMETERS!$D$27) -> 2868.9265 | ... R19: =Q19*(1+PARAMETERS!$D$27) -> 4313.8047 | S19: =IF(C19>0,(H19/C19)^(1/5)-1,0) -> 0.06 | T19: =IF(H19>0,(M19/H19)^(1/5)-1,0) -> 0.06 | U19: =IF(M19>0,(R19/M19)^(1/5)-1,0) -> 0.06 | V19: =IF(C19>0,R19/C19,0) -> 2.3965582
A20: Data Centers & Digitalization | B20: 4 | C20: =PARAMETERS!$C$16 -> 1200 | D20: =C20*(1+PARAMETERS!$D$28) -> 1260 | E20: =D20*(1+PARAMETERS!$D$28) -> 1323 | F20: =E20*(1+PARAMETERS!$D$28) -> 1389.15 | G20: =F20*(1+PARAMETERS!$D$28) -> 1458.6075 | H20: =G20*(1+PARAMETERS!$D$28) -> 1531.5379 | I20: =H20*(1+PARAMETERS!$D$28) -> 1608.1148 | J20: =I20*(1+PARAMETERS!$D$28) -> 1688.5205 | K20: =J20*(1+PARAMETERS!$D$28) -> 1772.9465 | ... R20: =Q20*(1+PARAMETERS!$D$28) -> 2494.7138 | S20: =IF(C20>0,(H20/C20)^(1/5)-1,0) -> 0.05 | T20: =IF(H20>0,(M20/H20)^(1/5)-1,0) -> 0.05 | U20: =IF(M20>0,(R20/M20)^(1/5)-1,0) -> 0.05 | V20: =IF(C20>0,R20/C20,0) -> 2.0789282
A21: Defense & Aerospace | B21: 5 | C21: =PARAMETERS!$C$17 -> 500 | D21: =C21*(1+PARAMETERS!$D$29) -> 520 | E21: =D21*(1+PARAMETERS!$D$29) -> 540.8 | F21: =E21*(1+PARAMETERS!$D$29) -> 562.432 | G21: =F21*(1+PARAMETERS!$D$29) -> 584.92928 | H21: =G21*(1+PARAMETERS!$D$29) -> 608.32645 | I21: =H21*(1+PARAMETERS!$D$29) -> 632.65951 | J21: =I21*(1+PARAMETERS!$D$29) -> 657.96589 | K21: =J21*(1+PARAMETERS!$D$29) -> 684.28453 | ... R21: =Q21*(1+PARAMETERS!$D$29) -> 900.47175 | S21: =IF(C21>0,(H21/C21)^(1/5)-1,0) -> 0.04 | T21: =IF(H21>0,(M21/H21)^(1/5)-1,0) -> 0.04 | U21: =IF(M21>0,(R21/M21)^(1/5)-1,0) -> 0.04 | V21: =IF(C21>0,R21/C21,0) -> 1.8009435
A22: Buildings & Construction | B22: 6 | C22: =PARAMETERS!$C$18 -> 7200 | D22: =C22*(1+PARAMETERS!$D$30) -> 7257.6 | E22: =D22*(1+PARAMETERS!$D$30) -> 7315.6608 | F22: =E22*(1+PARAMETERS!$D$30) -> 7374.1861 | G22: =F22*(1+PARAMETERS!$D$30) -> 7433.1796 | H22: =G22*(1+PARAMETERS!$D$30) -> 7492.645 | I22: =H22*(1+PARAMETERS!$D$30) -> 7552.5862 | J22: =I22*(1+PARAMETERS!$D$30) -> 7613.0069 | K22: =J22*(1+PARAMETERS!$D$30) -> 7673.9109 | ... R22: =Q22*(1+PARAMETERS!$D$30) -> 8114.1023 | S22: =IF(C22>0,(H22/C22)^(1/5)-1,0) -> 0.008 | T22: =IF(H22>0,(M22/H22)^(1/5)-1,0) -> 0.008 | U22: =IF(M22>0,(R22/M22)^(1/5)-1,0) -> 0.008 | V22: =IF(C22>0,R22/C22,0) -> 1.1269587
A23: Industrial Equipment & Machinery | B23: 7 | C23: =PARAMETERS!$C$19 -> 4000 | D23: =C23*(1+PARAMETERS!$D$31) -> 4048 | E23: =D23*(1+PARAMETERS!$D$31) -> 4096.576 | F23: =E23*(1+PARAMETERS!$D$31) -> 4145.7349 | G23: =F23*(1+PARAMETERS!$D$31) -> 4195.4837 | H23: =G23*(1+PARAMETERS!$D$31) -> 4245.8295 | I23: =H23*(1+PARAMETERS!$D$31) -> 4296.7795 | J23: =I23*(1+PARAMETERS!$D$31) -> 4348.3408 | K23: =J23*(1+PARAMETERS!$D$31) -> 4400.5209 | ... R23: =Q23*(1+PARAMETERS!$D$31) -> 4783.7412 | S23: =IF(C23>0,(H23/C23)^(1/5)-1,0) -> 0.012 | T23: =IF(H23>0,(M23/H23)^(1/5)-1,0) -> 0.012 | U23: =IF(M23>0,(R23/M23)^(1/5)-1,0) -> 0.012 | V23: =IF(C23>0,R23/C23,0) -> 1.1959353
A24: Appliances, Electronics & Other | B24: 8 | C24: =PARAMETERS!$C$20 -> 3000 | D24: =C24*(1+PARAMETERS!$D$32) -> 3030 | E24: =D24*(1+PARAMETERS!$D$32) -> 3060.3 | F24: =E24*(1+PARAMETERS!$D$32) -> 3090.903 | G24: =F24*(1+PARAMETERS!$D$32) -> 3121.812 | H24: =G24*(1+PARAMETERS!$D$32) -> 3153.0302 | I24: =H24*(1+PARAMETERS!$D$32) -> 3184.5605 | J24: =I24*(1+PARAMETERS!$D$32) -> 3216.4061 | K24: =J24*(1+PARAMETERS!$D$32) -> 3248.5701 | ... R24: =Q24*(1+PARAMETERS!$D$32) -> 3482.9069 | S24: =IF(C24>0,(H24/C24)^(1/5)-1,0) -> 0.01 | T24: =IF(H24>0,(M24/H24)^(1/5)-1,0) -> 0.01 | U24: =IF(M24>0,(R24/M24)^(1/5)-1,0) -> 0.01 | V24: =IF(C24>0,R24/C24,0) -> 1.160969
A25: TOTAL — REALISTIC SCENARIO | C25: =SUM(C17:C24) -> 26000 | D25: =SUM(D17:D24) -> 26698.1 | E25: =SUM(E17:E24) -> 27426.384 | F25: =SUM(F17:F24) -> 28186.442 | G25: =SUM(G17:G24) -> 28979.953 | H25: =SUM(H17:H24) -> 29808.692 | I25: =SUM(I17:I24) -> 30674.538 | J25: =SUM(J17:J24) -> 31579.473 | ... R25: =SUM(R17:R24) -> 40505.314 | S25: =IF(C25>0,(H25/C25)^(1/5)-1,0) -> 0.027717887 | T25: =IF(H25>0,(M25/H25)^(1/5)-1,0) -> 0.029964072 | U25: =IF(M25>0,(R25/M25)^(1/5)-1,0) -> 0.032313817 | V25: =IF(C25>0,R25/C25,0) -> 1.5578967
A27: LOW SCENARIO
A28: Power Grid & Transmission | B28: 1 | C28: =PARAMETERS!$C$13 -> 5500 | D28: =C28*(1+PARAMETERS!$E$25) -> 5599 | E28: =D28*(1+PARAMETERS!$E$25) -> 5699.782 | F28: =E28*(1+PARAMETERS!$E$25) -> 5802.3781 | G28: =F28*(1+PARAMETERS!$E$25) -> 5906.8209 | H28: =G28*(1+PARAMETERS!$E$25) -> 6013.1437 | I28: =H28*(1+PARAMETERS!$E$25) -> 6121.3802 | J28: =I28*(1+PARAMETERS!$E$25) -> 6231.5651 | K28: =J28*(1+PARAMETERS!$E$25) -> 6343.7333 | ... R28: =Q28*(1+PARAMETERS!$E$25) -> 7187.5249 | S28: =IF(C28>0,(H28/C28)^(1/5)-1,0) -> 0.018 | T28: =IF(H28>0,(M28/H28)^(1/5)-1,0) -> 0.018 | U28: =IF(M28>0,(R28/M28)^(1/5)-1,0) -> 0.018 | V28: =IF(C28>0,R28/C28,0) -> 1.3068227
A29: Electric Vehicles (EVs) | B29: 2 | C29: =PARAMETERS!$C$14 -> 2800 | D29: =C29*(1+PARAMETERS!$E$26) -> 2912 | E29: =D29*(1+PARAMETERS!$E$26) -> 3028.48 | F29: =E29*(1+PARAMETERS!$E$26) -> 3149.6192 | G29: =F29*(1+PARAMETERS!$E$26) -> 3275.604 | H29: =G29*(1+PARAMETERS!$E$26) -> 3406.6281 | I29: =H29*(1+PARAMETERS!$E$26) -> 3542.8933 | J29: =I29*(1+PARAMETERS!$E$26) -> 3684.609 | K29: =J29*(1+PARAMETERS!$E$26) -> 3831.9933 | ... R29: =Q29*(1+PARAMETERS!$E$26) -> 5042.6418 | S29: =IF(C29>0,(H29/C29)^(1/5)-1,0) -> 0.04 | T29: =IF(H29>0,(M29/H29)^(1/5)-1,0) -> 0.04 | U29: =IF(M29>0,(R29/M29)^(1/5)-1,0) -> 0.04 | V29: =IF(C29>0,R29/C29,0) -> 1.8009435
A30: Renewable Energy (Solar & Wind) | B30: 3 | C30: =PARAMETERS!$C$15 -> 1800 | D30: =C30*(1+PARAMETERS!$E$27) -> 1868.4 | E30: =D30*(1+PARAMETERS!$E$27) -> 1939.3992 | F30: =E30*(1+PARAMETERS!$E$27) -> 2013.0964 | G30: =F30*(1+PARAMETERS!$E$27) -> 2089.594 | H30: =G30*(1+PARAMETERS!$E$27) -> 2168.9986 | I30: =H30*(1+PARAMETERS!$E$27) -> 2251.4206 | J30: =I30*(1+PARAMETERS!$E$27) -> 2336.9745 | K30: =J30*(1+PARAMETERS!$E$27) -> 2425.7796 | ... R30: =Q30*(1+PARAMETERS!$E$27) -> 3149.4361 | S30: =IF(C30>0,(H30/C30)^(1/5)-1,0) -> 0.038 | T30: =IF(H30>0,(M30/H30)^(1/5)-1,0) -> 0.038 | U30: =IF(M30>0,(R30/M30)^(1/5)-1,0) -> 0.038 | V30: =IF(C30>0,R30/C30,0) -> 1.7496867
A31: Data Centers & Digitalization | B31: 4 | C31: =PARAMETERS!$C$16 -> 1200 | D31: =C31*(1+PARAMETERS!$E$28) -> 1236 | E31: =D31*(1+PARAMETERS!$E$28) -> 1273.08 | F31: =E31*(1+PARAMETERS!$E$28) -> 1311.2724 | G31: =F31*(1+PARAMETERS!$E$28) -> 1350.6106 | H31: =G31*(1+PARAMETERS!$E$28) -> 1391.1289 | I31: =H31*(1+PARAMETERS!$E$28) -> 1432.8628 | J31: =I31*(1+PARAMETERS!$E$28) -> 1475.8486 | K31: =J31*(1+PARAMETERS!$E$28) -> 1520.1241 | ... R31: =Q31*(1+PARAMETERS!$E$28) -> 1869.5609 | S31: =IF(C31>0,(H31/C31)^(1/5)-1,0) -> 0.03 | T31: =IF(H31>0,(M31/H31)^(1/5)-1,0) -> 0.03 | U31: =IF(M31>0,(R31/M31)^(1/5)-1,0) -> 0.03 | V31: =IF(C31>0,R31/C31,0) -> 1.5579674
A32: Defense & Aerospace | B32: 5 | C32: =PARAMETERS!$C$17 -> 500 | D32: =C32*(1+PARAMETERS!$E$29) -> 512.5 | E32: =D32*(1+PARAMETERS!$E$29) -> 525.3125 | F32: =E32*(1+PARAMETERS!$E$29) -> 538.44531 | G32: =F32*(1+PARAMETERS!$E$29) -> 551.90645 | H32: =G32*(1+PARAMETERS!$E$29) -> 565.70411 | I32: =H32*(1+PARAMETERS!$E$29) -> 579.84671 | J32: =I32*(1+PARAMETERS!$E$29) -> 594.34288 | K32: =J32*(1+PARAMETERS!$E$29) -> 609.20145 | ... R32: =Q32*(1+PARAMETERS!$E$29) -> 724.14908 | S32: =IF(C32>0,(H32/C32)^(1/5)-1,0) -> 0.025 | T32: =IF(H32>0,(M32/H32)^(1/5)-1,0) -> 0.025 | U32: =IF(M32>0,(R32/M32)^(1/5)-1,0) -> 0.025 | V32: =IF(C32>0,R32/C32,0) -> 1.4482982
A33: Buildings & Construction | B33: 6 | C33: =PARAMETERS!$C$18 -> 7200 | D33: =C33*(1+PARAMETERS!$E$30) -> 7214.4 | E33: =D33*(1+PARAMETERS!$E$30) -> 7228.8288 | F33: =E33*(1+PARAMETERS!$E$30) -> 7243.2865 | G33: =F33*(1+PARAMETERS!$E$30) -> 7257.773 | H33: =G33*(1+PARAMETERS!$E$30) -> 7272.2886 | I33: =H33*(1+PARAMETERS!$E$30) -> 7286.8332 | J33: =I33*(1+PARAMETERS!$E$30) -> 7301.4068 | K33: =J33*(1+PARAMETERS!$E$30) -> 7316.0096 | ... R33: =Q33*(1+PARAMETERS!$E$30) -> 7419.0504 | S33: =IF(C33>0,(H33/C33)^(1/5)-1,0) -> 0.002 | T33: =IF(H33>0,(M33/H33)^(1/5)-1,0) -> 0.002 | U33: =IF(M33>0,(R33/M33)^(1/5)-1,0) -> 0.002 | V33: =IF(C33>0,R33/C33,0) -> 1.0304237
A34: Industrial Equipment & Machinery | B34: 7 | C34: =PARAMETERS!$C$19 -> 4000 | D34: =C34*(1+PARAMETERS!$E$31) -> 4020 | E34: =D34*(1+PARAMETERS!$E$31) -> 4040.1 | F34: =E34*(1+PARAMETERS!$E$31) -> 4060.3005 | G34: =F34*(1+PARAMETERS!$E$31) -> 4080.602 | H34: =G34*(1+PARAMETERS!$E$31) -> 4101.005 | I34: =H34*(1+PARAMETERS!$E$31) -> 4121.51 | J34: =I34*(1+PARAMETERS!$E$31) -> 4142.1176 | K34: =J34*(1+PARAMETERS!$E$31) -> 4162.8282 | ... R34: =Q34*(1+PARAMETERS!$E$31) -> 4310.731 | S34: =IF(C34>0,(H34/C34)^(1/5)-1,0) -> 0.005 | T34: =IF(H34>0,(M34/H34)^(1/5)-1,0) -> 0.005 | U34: =IF(M34>0,(R34/M34)^(1/5)-1,0) -> 0.005 | V34: =IF(C34>0,R34/C34,0) -> 1.0776827
A35: Appliances, Electronics & Other | B35: 8 | C35: =PARAMETERS!$C$20 -> 3000 | D35: =C35*(1+PARAMETERS!$E$32) -> 3009 | E35: =D35*(1+PARAMETERS!$E$32) -> 3018.027 | F35: =E35*(1+PARAMETERS!$E$32) -> 3027.0811 | G35: =F35*(1+PARAMETERS!$E$32) -> 3036.1623 | H35: =G35*(1+PARAMETERS!$E$32) -> 3045.2708 | I35: =H35*(1+PARAMETERS!$E$32) -> 3054.4066 | J35: =I35*(1+PARAMETERS!$E$32) -> 3063.5698 | K35: =J35*(1+PARAMETERS!$E$32) -> 3072.7606 | ... R35: =Q35*(1+PARAMETERS!$E$32) -> 3137.8722 | S35: =IF(C35>0,(H35/C35)^(1/5)-1,0) -> 0.003 | T35: =IF(H35>0,(M35/H35)^(1/5)-1,0) -> 0.003 | U35: =IF(M35>0,(R35/M35)^(1/5)-1,0) -> 0.003 | V35: =IF(C35>0,R35/C35,0) -> 1.0459574
A36: TOTAL — LOW SCENARIO | C36: =SUM(C28:C35) -> 26000 | D36: =SUM(D28:D35) -> 26371.3 | E36: =SUM(E28:E35) -> 26753.009 | F36: =SUM(F28:F35) -> 27145.479 | G36: =SUM(G28:G35) -> 27549.073 | H36: =SUM(H28:H35) -> 27964.168 | I36: =SUM(I28:I35) -> 28391.153 | J36: =SUM(J28:J35) -> 28830.434 | ... R36: =SUM(R28:R35) -> 32840.966 | S36: =IF(C36>0,(H36/C36)^(1/5)-1,0) -> 0.01467208 | T36: =IF(H36>0,(M36/H36)^(1/5)-1,0) -> 0.015679465 | U36: =IF(M36>0,(R36/M36)^(1/5)-1,0) -> 0.01673116 | V36: =IF(C36>0,R36/C36,0) -> 1.2631141

Sheet ARGENTINA_SUPPLY
A1: ARGENTINA SUPPLY POTENTIAL — Mining Output 2025–2040 (kt)
A3: Mine / Project | B3: Province | C3: 2025 | D3: 2026 | E3: 2027 | F3: 2028 | G3: 2029 | H3: 2030 | I3: 2031 | J3: 2032 | K3: 2033 | L3: 2034 | M3: 2035 | N3: 2036 | O3: 2037 | P3: 2038 | Q3: 2039 | R3: 2040 | S3: Total 2025-30 (kt) | T3: Total 2031-35 (kt) | U3: Total 2036-40 (kt) | V3: Peak Output (kt)
A4: Annual production modelled as: ramp-up in first 2 years (50%→75%→100%), 1% annual depletion on operating mines, zero after end of mine life.
A5: CONSERVATIVE SCENARIO
A6: Bajo de la Alumbrera* | B6: Catamarca | C6: 35 | D6: 52 | E6: 69 | F6: 68 | G6: 67 | H6: 67 | I6: 0 | J6: 0 | K6: 0 | L6: 0 | M6: 0 | N6: 0 | O6: 0 | P6: 0 | Q6: 0 | R6: 0 | S6: =SUM(C6:H6) -> 358 | T6: =SUM(I6:M6) -> 0 | U6: =SUM(N6:R6) -> 0 | V6: =MAX(E6:R6) -> 69
A7: MARA (Agua Rica) | B7: Catamarca | C7: 0 | D7: 0 | E7: 0 | F7: 0 | G7: 0 | H7: 0 | I7: 0 | J7: 0 | K7: 0 | L7: 0 | M7: 0 | N7: 0 | O7: 0 | P7: 0 | Q7: 0 | R7: 0 | S7: 0 | T7: 0 | U7: 0 | V7: 0
A8: Josemaría | B8: San Juan | C8: 0 | D8: 0 | E8: 0 | F8: 0 | G8: 0 | H8: 0 | I8: 0 | J8: 0 | K8: 0 | L8: 0 | M8: 0 | N8: 0 | O8: 0 | P8: 0 | Q8: 0 | R8: 0 | S8: 0 | T8: 0 | U8: 0 | V8: 0
A9: El Pachón | B9: San Juan | C9: 0 | D9: 0 | E9: 0 | F9: 0 | G9: 0 | H9: 0 | I9: 0 | J9: 0 | K9: 0 | L9: 0 | M9: 0 | N9: 0 | O9: 0 | P9: 0 | Q9: 0 | R9: 0 | S9: 0 | T9: 0 | U9: 0 | V9: 0
A10: Los Azules | B10: San Juan | C10: 0 | D10: 0 | E10: 0 | F10: 0 | G10: 0 | H10: 0 | I10: 0 | J10: 0 | K10: 0 | L10: 0 | M10: 0 | N10: 0 | O10: 0 | P10: 0 | Q10: 0 | R10: 0 | S10: 0 | T10: 0 | U10: 0 | V10: 0
A11: Taca Taca | B11: Salta | C11: 0 | D11: 0 | E11: 0 | F11: 0 | G11: 0 | H11: 0 | I11: 0 | J11: 0 | K11: 0 | L11: 0 | M11: 0 | N11: 0 | O11: 0 | P11: 0 | Q11: 0 | R11: 0 | S11: 0 | T11: 0 | U11: 0 | V11: 0
A12: Altar | B12: San Juan | C12: 0 | D12: 0 | E12: 0 | F12: 0 | G12: 0 | H12: 0 | I12: 0 | J12: 0 | K12: 0 | L12: 0 | M12: 0 | N12: 0 | O12: 0 | P12: 0 | Q12: 0 | R12: 0 | S12: 0 | T12: 0 | U12: 0 | V12: 0
A13: San Jorge | B13: Mendoza | C13: 0 | D13: 0 | E13: 0 | F13: 0 | G13: 0 | H13: 0 | I13: 0 | J13: 0 | K13: 0 | L13: 0 | M13: 0 | N13: 0 | O13: 0 | P13: 0 | Q13: 0 | R13: 0 | S13: 0 | T13: 0 | U13: 0 | V13: 0
A14: TOTAL ARGENTINA — CONSERVATIVE SCENARIO | C14: =SUM(C6:C13) -> 35 | D14: =SUM(D6:D13) -> 52 | E14: =SUM(E6:E13) -> 69 | F14: =SUM(F6:F13) -> 68 | G14: =SUM(G6:G13) -> 67 | H14: =SUM(H6:H13) -> 67 | I14: =SUM(I6:I13) -> 0 | J14: =SUM(J6:J13) -> 0 | ... V14: =SUM(V6:V13) -> 69
A16: BASE SCENARIO
A17: Bajo de la Alumbrera* | B17: Catamarca | C17: 35 | D17: 52 | E17: 69 | F17: 68 | G17: 67 | H17: 67 | I17: 0 | J17: 0 | K17: 0 | L17: 0 | M17: 0 | N17: 0 | O17: 0 | P17: 0 | Q17: 0 | R17: 0 | S17: =SUM(C17:H17) -> 358 | T17: =SUM(I17:M17) -> 0 | U17: =SUM(N17:R17) -> 0 | V17: =MAX(E17:R17) -> 69
A18: MARA (Agua Rica) | B18: Catamarca | C18: 0 | D18: 0 | E18: 0 | F18: 0 | G18: 100 | H18: 150 | I18: 200 | J18: 200 | K18: 200 | L18: 200 | M18: 200 | N18: 200 | O18: 200 | P18: 200 | Q18: 200 | R18: 200 | S18: =SUM(C18:H18) -> 250 | T18: =SUM(I18:M18) -> 1000 | U18: =SUM(N18:R18) -> 1000 | V18: =MAX(I18:R18) -> 200
A19: Josemaría | B19: San Juan | C19: 0 | D19: 0 | E19: 0 | F19: 0 | G19: 0 | H19: 0 | I19: 75 | J19: 112 | K19: 150 | L19: 150 | M19: 150 | N19: 150 | O19: 150 | P19: 150 | Q19: 150 | R19: 150 | S19: =SUM(C19:H19) -> 0 | T19: =SUM(I19:M19) -> 637 | U19: =SUM(N19:R19) -> 750 | V19: =MAX(K19:R19) -> 150
A20: El Pachón | B20: San Juan | C20: 0 | D20: 0 | E20: 0 | F20: 0 | G20: 0 | H20: 0 | I20: 0 | J20: 0 | K20: 0 | L20: 0 | M20: 0 | N20: 0 | O20: 0 | P20: 0 | Q20: 0 | R20: 0 | S20: 0 | T20: 0 | U20: 0 | V20: 0
A21: Los Azules | B21: San Juan | C21: 0 | D21: 0 | E21: 0 | F21: 0 | G21: 0 | H21: 0 | I21: 0 | J21: 0 | K21: 0 | L21: 0 | M21: 0 | N21: 0 | O21: 0 | P21: 0 | Q21: 0 | R21: 0 | S21: 0 | T21: 0 | U21: 0 | V21: 0
A22: Taca Taca | B22: Salta | C22: 0 | D22: 0 | E22: 0 | F22: 0 | G22: 0 | H22: 0 | I22: 0 | J22: 0 | K22: 0 | L22: 0 | M22: 0 | N22: 0 | O22: 0 | P22: 0 | Q22: 0 | R22: 0 | S22: 0 | T22: 0 | U22: 0 | V22: 0
A23: Altar | B23: San Juan | C23: 0 | D23: 0 | E23: 0 | F23: 0 | G23: 0 | H23: 0 | I23: 0 | J23: 0 | K23: 0 | L23: 0 | M23: 0 | N23: 0 | O23: 0 | P23: 0 | Q23: 0 | R23: 0 | S23: 0 | T23: 0 | U23: 0 | V23: 0
A24: San Jorge | B24: Mendoza | C24: 0 | D24: 0 | E24: 0 | F24: 0 | G24: 0 | H24: 0 | I24: 0 | J24: 0 | K24: 0 | L24: 0 | M24: 0 | N24: 0 | O24: 0 | P24: 0 | Q24: 0 | R24: 0 | S24: 0 | T24: 0 | U24: 0 | V24: 0
A25: TOTAL ARGENTINA — BASE SCENARIO | C25: =SUM(C17:C24) -> 35 | D25: =SUM(D17:D24) -> 52 | E25: =SUM(E17:E24) -> 69 | F25: =SUM(F17:F24) -> 68 | G25: =SUM(G17:G24) -> 167 | H25: =SUM(H17:H24) -> 217 | I25: =SUM(I17:I24) -> 275 | J25: =SUM(J17:J24) -> 312 | ... V25: =SUM(V17:V24) -> 419
A27: MAXIMUM SCENARIO
A28: Bajo de la Alumbrera* | B28: Catamarca | C28: 35 | D28: 52 | E28: 69 | F28: 68 | G28: 67 | H28: 67 | I28: 0 | J28: 0 | K28: 0 | L28: 0 | M28: 0 | N28: 0 | O28: 0 | P28: 0 | Q28: 0 | R28: 0 | S28: =SUM(C28:H28) -> 358 | T28: =SUM(I28:M28) -> 0 | U28: =SUM(N28:R28) -> 0 | V28: =MAX(E28:R28) -> 69
A29: MARA (Agua Rica) | B29: Catamarca | C29: 0 | D29: 0 | E29: 0 | F29: 0 | G29: 100 | H29: 150 | I29: 200 | J29: 200 | K29: 200 | L29: 200 | M29: 200 | N29: 200 | O29: 200 | P29: 200 | Q29: 200 | R29: 200 | S29: =SUM(C29:H29) -> 250 | T29: =SUM(I29:M29) -> 1000 | U29: =SUM(N29:R29) -> 1000 | V29: =MAX(I29:R29) -> 200
A30: Josemaría | B30: San Juan | C30: 0 | D30: 0 | E30: 0 | F30: 0 | G30: 0 | H30: 0 | I30: 75 | J30: 112 | K30: 150 | L30: 150 | M30: 150 | N30: 150 | O30: 150 | P30: 150 | Q30: 150 | R30: 150 | S30: =SUM(C30:H30) -> 0 | T30: =SUM(I30:M30) -> 637 | U30: =SUM(N30:R30) -> 750 | V30: =MAX(K30:R30) -> 150
A31: El Pachón | B31: San Juan | C31: 0 | D31: 0 | E31: 0 | F31: 0 | G31: 0 | H31: 0 | I31: 0 | J31: 100 | K31: 150 | L31: 200 | M31: 200 | N31: 200 | O31: 200 | P31: 200 | Q31: 200 | R31: 200 | S31: =SUM(C31:H31) -> 0 | T31: =SUM(I31:M31) -> 650 | U31: =SUM(N31:R31) -> 1000 | V31: =MAX(L31:R31) -> 200
A32: Los Azules | B32: San Juan | C32: 0 | D32: 0 | E32: 0 | F32: 0 | G32: 0 | H32: 0 | I32: 0 | J32: 0 | K32: 100 | L32: 150 | M32: 200 | N32: 200 | O32: 200 | P32: 200 | Q32: 200 | R32: 200 | S32: =SUM(C32:H32) -> 0 | T32: =SUM(I32:M32) -> 450 | U32: =SUM(N32:R32) -> 1000 | V32: =MAX(M32:R32) -> 200
A33: Taca Taca | B33: Salta | C33: 0 | D33: 0 | E33: 0 | F33: 0 | G33: 0 | H33: 0 | I33: 0 | J33: 0 | K33: 85 | L33: 128 | M33: 170 | N33: 170 | O33: 170 | P33: 170 | Q33: 170 | R33: 170 | S33: =SUM(C33:H33) -> 0 | T33: =SUM(I33:M33) -> 383 | U33: =SUM(N33:R33) -> 850 | V33: =MAX(M33:R33) -> 170
A34: Altar | B34: San Juan | C34: 0 | D34: 0 | E34: 0 | F34: 0 | G34: 0 | H34: 0 | I34: 0 | J34: 0 | K34: 0 | L34: 0 | M34: 50 | N34: 75 | O34: 100 | P34: 100 | Q34: 100 | R34: 100 | S34: =SUM(C34:H34) -> 0 | T34: =SUM(I34:M34) -> 50 | U34: =SUM(N34:R34) -> 475 | V34: =MAX(O34:R34) -> 100
A35: San Jorge | B35: Mendoza | C35: 0 | D35: 0 | E35: 0 | F35: 0 | G35: 0 | H35: 0 | I35: 0 | J35: 0 | K35: 0 | L35: 35 | M35: 52 | N35: 70 | O35: 70 | P35: 70 | Q35: 70 | R35: 70 | S35: =SUM(C35:H35) -> 0 | T35: =SUM(I35:M35) -> 87 | U35: =SUM(N35:R35) -> 350 | V35: =MAX(N35:R35) -> 70
A36: TOTAL ARGENTINA — MAXIMUM SCENARIO | C36: =SUM(C28:C35) -> 35 | D36: =SUM(D28:D35) -> 52 | E36: =SUM(E28:E35) -> 69 | F36: =SUM(F28:F35) -> 68 | G36: =SUM(G28:G35) -> 167 | H36: =SUM(H28:H35) -> 217 | I36: =SUM(I28:I35) -> 275 | J36: =SUM(J28:J35) -> 412 | ... V36: =SUM(V28:V35) -> 1159
A38: * Alumbrera mine life nearing end; output ramps down. CONSERVATIVE = currently operating/development-ready only. BASE = adds near-term approved projects. MAXIMUM = full identified pipeline.

Sheet MARKET_GAP
A1: MARKET GAP ANALYSIS — Global Supply-Demand Balance & Argentina's Addressable Opportunity (kt)
A2: Rows reference DEMAND_FORECAST totals (rows 14, 24, 34) and ARGENTINA_SUPPLY totals. Global supply estimate: 2025 global mine supply ~22,000 kt + primary smelter output ~26,500 kt (net refined). Note: 'Gap' = incremental demand above 2025; Argentina 'Opportunity' = Gap × assumed market share.
A3: Line Item / Scenario | B3: Units | C3: 2025 | D3: 2026 | E3: 2027 | F3: 2028 | G3: 2029 | H3: 2030 | I3: 2031 | J3: 2032 | K3: 2033 | L3: 2034 | M3: 2035 | N3: 2036 | O3: 2037 | P3: 2038 | Q3: 2039 | R3: 2040 | S3: Cum. 2025-30 (kt) | T3: Cum. 2031-35 (kt) | U3: Cum. 2036-40 (kt)
A4: HIGH DEMAND / MAXIMUM SUPPLY
A5: Global CRM Demand | B5: kt | C5: =DEMAND_FORECAST!C14 -> 26000 | D5: =DEMAND_FORECAST!D14 -> 27012 | E5: =DEMAND_FORECAST!E14 -> 28082.715 | F5: =DEMAND_FORECAST!F14 -> 29216.299 | G5: =DEMAND_FORECAST!G14 -> 30417.228 | H5: =DEMAND_FORECAST!H14 -> 31690.323 | I5: =DEMAND_FORECAST!I14 -> 33040.781 | J5: =DEMAND_FORECAST!J14 -> 34474.205 | ... R5: =DEMAND_FORECAST!R14 -> 49763.289 | S5: =SUM(C5:H5) -> 172418.57 | T5: =SUM(I5:M5) -> 180461.3 | U5: =SUM(N5:R5) -> 226637.96
A6: Global CRM Supply* | B6: kt | C6: =26000*(1+0.02)^0 -> 26000 | D6: =26000*(1+0.02)^1 -> 26520 | E6: =26000*(1+0.02)^2 -> 27050.4 | F6: =26000*(1+0.02)^3 -> 27591.408 | G6: =26000*(1+0.02)^4 -> 28143.236 | H6: =26000*(1+0.02)^5 -> 28706.101 | I6: =26000*(1+0.02)^6 -> 29280.223 | J6: =26000*(1+0.02)^7 -> 29865.827 | K6: =26000*(1+0.02)^8 -> 30463.144 | L6: =26000*(1+0.02)^9 -> 31072.407 | M6: =26000*(1+0.02)^10 -> 31693.855 | N6: =26000*(1+0.02)^11 -> 32327.732 | O6: =26000*(1+0.02)^12 -> 32974.287 | P6: =26000*(1+0.02)^13 -> 33633.772 | Q6: =26000*(1+0.02)^14 -> 34306.448 | R6: =26000*(1+0.02)^15 -> 34992.577 | S6: =SUM(C6:H6) -> 164011.15 | T6: =SUM(I6:M6) -> 152375.46 | U6: =SUM(N6:R6) -> 168234.82
A7: DEMAND-SUPPLY GAP | B7: kt | C7: =C5-C6 -> 0 | D7: =D5-D6 -> 492 | E7: =E5-E6 -> 1032.315 | F7: =F5-F6 -> 1624.8913 | G7: =G5-G6 -> 2273.9918 | H7: =H5-H6 -> 2984.2222 | I7: =I5-I6 -> 3760.5585 | J7: =J5-J6 -> 4608.378 | ... R7: =R5-R6 -> 14770.712 | S7: =SUM(C7:H7) -> 8407.4202 | T7: =SUM(I7:M7) -> 28085.84 | U7: =SUM(N7:R7) -> 58403.144
A8: Argentina Supply | B8: kt | C8: =ARGENTINA_SUPPLY!C36 -> 35 | D8: =ARGENTINA_SUPPLY!D36 -> 52 | E8: =ARGENTINA_SUPPLY!E36 -> 69 | F8: =ARGENTINA_SUPPLY!F36 -> 68 | G8: =ARGENTINA_SUPPLY!G36 -> 167 | H8: =ARGENTINA_SUPPLY!H36 -> 217 | I8: =ARGENTINA_SUPPLY!I36 -> 275 | J8: =ARGENTINA_SUPPLY!J36 -> 412 | ... R8: =ARGENTINA_SUPPLY!R36 -> 1090 | S8: =SUM(C8:H8) -> 608 | T8: =SUM(I8:M8) -> 3257 | U8: =SUM(N8:R8) -> 5425
A9: Remaining Gap after AR | B9: kt | C9: =C7-C8 -> -35 | D9: =D7-D8 -> 440 | E9: =E7-E8 -> 963.315 | F9: =F7-F8 -> 1556.8913 | G9: =G7-G8 -> 2106.9918 | H9: =H7-H8 -> 2767.2222 | I9: =I7-I8 -> 3485.5585 | J9: =J7-J8 -> 4196.378 | ... R9: =R7-R8 -> 13680.712 | S9: =SUM(C9:H9) -> 7799.4202 | T9: =SUM(I9:M9) -> 24828.84 | U9: =SUM(N9:R9) -> 52978.144
A10: Argentina Market Share | B10: % | C10: =IF(C5>0,C8/C5,0) -> 0.0013461538 | D10: =IF(D5>0,D8/D5,0) -> 0.0019250703 | E10: =IF(E5>0,E8/E5,0) -> 0.0024570274 | F10: =IF(F5>0,F8/F5,0) -> 0.0023274679 | G10: =IF(G5>0,G8/G5,0) -> 0.0054903096 | H10: =IF(H5>0,H8/H5,0) -> 0.0068475162 | I10: =IF(I5>0,I8/I5,0) -> 0.0083230477 | J10: =IF(J5>0,J8/J5,0) -> 0.011950964 | ... R10: =IF(R5>0,R8/R5,0) -> 0.021903697 | S10: =SUM(C10:H10) -> 0.020393545 | T10: =SUM(I10:M10) -> 0.088228688 | U10: =SUM(N10:R10) -> 0.1201702
A12: REALISTIC DEMAND / BASE SUPPLY
A13: Global CRM Demand | B13: kt | C13: =DEMAND_FORECAST!C25 -> 26000 | D13: =DEMAND_FORECAST!D25 -> 26698.1 | E13: =DEMAND_FORECAST!E25 -> 27426.384 | F13: =DEMAND_FORECAST!F25 -> 28186.442 | G13: =DEMAND_FORECAST!G25 -> 28979.953 | H13: =DEMAND_FORECAST!H25 -> 29808.692 | I13: =DEMAND_FORECAST!I25 -> 30674.538 | J13: =DEMAND_FORECAST!J25 -> 31579.473 | ... R13: =DEMAND_FORECAST!R25 -> 40505.314 | S13: =SUM(C13:H13) -> 167099.57 | T13: =SUM(I13:M13) -> 162845.15 | U13: =SUM(N13:R13) -> 190064.96
A14: Global CRM Supply* | B14: kt | C14: =26000*(1+0.014)^0 -> 26000 | D14: =26000*(1+0.014)^1 -> 26364 | E14: =26000*(1+0.014)^2 -> 26733.096 | F14: =26000*(1+0.014)^3 -> 27107.359 | G14: =26000*(1+0.014)^4 -> 27486.862 | H14: =26000*(1+0.014)^5 -> 27871.678 | I14: =26000*(1+0.014)^6 -> 28261.882 | J14: =26000*(1+0.014)^7 -> 28657.548 | K14: =26000*(1+0.014)^8 -> 29058.754 | L14: =26000*(1+0.014)^9 -> 29465.577 | M14: =26000*(1+0.014)^10 -> 29878.095 | N14: =26000*(1+0.014)^11 -> 30296.388 | O14: =26000*(1+0.014)^12 -> 30720.537 | P14: =26000*(1+0.014)^13 -> 31150.625 | Q14: =26000*(1+0.014)^14 -> 31586.734 | R14: =26000*(1+0.014)^15 -> 32028.948 | S14: =SUM(C14:H14) -> 161563 | T14: =SUM(I14:M14) -> 145321.86 | U14: =SUM(N14:R14) -> 155783.23
A15: DEMAND-SUPPLY GAP | B15: kt | C15: =C13-C14 -> 0 | D15: =D13-D14 -> 334.1 | E15: =E13-E14 -> 693.2883 | F15: =F13-F14 -> 1079.0827 | G15: =G13-G14 -> 1493.0906 | H15: =H13-H14 -> 1937.014 | I15: =I13-I14 -> 2412.6556 | J15: =J13-J14 -> 2921.9246 | ... R15: =R13-R14 -> 8476.3662 | S15: =SUM(C15:H15) -> 5536.5755 | T15: =SUM(I15:M15) -> 17523.3 | U15: =SUM(N15:R15) -> 34281.732
A16: Argentina Supply | B16: kt | C16: =ARGENTINA_SUPPLY!C25 -> 35 | D16: =ARGENTINA_SUPPLY!D25 -> 52 | E16: =ARGENTINA_SUPPLY!E25 -> 69 | F16: =ARGENTINA_SUPPLY!F25 -> 68 | G16: =ARGENTINA_SUPPLY!G25 -> 167 | H16: =ARGENTINA_SUPPLY!H25 -> 217 | I16: =ARGENTINA_SUPPLY!I25 -> 275 | J16: =ARGENTINA_SUPPLY!J25 -> 312 | ... R16: =ARGENTINA_SUPPLY!R25 -> 350 | S16: =SUM(C16:H16) -> 608 | T16: =SUM(I16:M16) -> 1637 | U16: =SUM(N16:R16) -> 1750
A17: Remaining Gap after AR | B17: kt | C17: =C15-C16 -> -35 | D17: =D15-D16 -> 282.1 | E17: =E15-E16 -> 624.2883 | F17: =F15-F16 -> 1011.0827 | G17: =G15-G16 -> 1326.0906 | H17: =H15-H16 -> 1720.014 | I17: =I15-I16 -> 2137.6556 | J17: =J15-J16 -> 2609.9246 | ... R17: =R15-R16 -> 8126.3662 | S17: =SUM(C17:H17) -> 4928.5755 | T17: =SUM(I17:M17) -> 15886.3 | U17: =SUM(N17:R17) -> 32531.732
A18: Argentina Market Share | B18: % | C18: =IF(C13>0,C16/C13,0) -> 0.0013461538 | D18: =IF(D13>0,D16/D13,0) -> 0.0019477041 | E18: =IF(E13>0,E16/E13,0) -> 0.0025158256 | F18: =IF(F13>0,F16/F13,0) -> 0.0024125074 | G18: =IF(G13>0,G16/G13,0) -> 0.0057626043 | H18: =IF(H13>0,H16/H13,0) -> 0.0072797558 | I18: =IF(I13>0,I16/I13,0) -> 0.0089650903 | J18: =IF(J13>0,J16/J13,0) -> 0.0098798356 | ... R18: =IF(R13>0,R16/R13,0) -> 0.0086408415 | S18: =SUM(C18:H18) -> 0.021264551 | T18: =SUM(I18:M18) -> 0.05017885 | U18: =SUM(N18:R18) -> 0.046131454
A20: LOW DEMAND / CONSERVATIVE SUPPLY
A21: Global CRM Demand | B21: kt | C21: =DEMAND_FORECAST!C36 -> 26000 | D21: =DEMAND_FORECAST!D36 -> 26371.3 | E21: =DEMAND_FORECAST!E36 -> 26753.009 | F21: =DEMAND_FORECAST!F36 -> 27145.479 | G21: =DEMAND_FORECAST!G36 -> 27549.073 | H21: =DEMAND_FORECAST!H36 -> 27964.168 | I21: =DEMAND_FORECAST!I36 -> 28391.153 | J21: =DEMAND_FORECAST!J36 -> 28830.434 | ... R21: =DEMAND_FORECAST!R36 -> 32840.966 | S21: =SUM(C21:H21) -> 161783.03 | T21: =SUM(I21:M21) -> 146477.91 | U21: =SUM(N21:R21) -> 158822.36
A22: Global CRM Supply* | B22: kt | C22: =26000*(1+0.007)^0 -> 26000 | D22: =26000*(1+0.007)^1 -> 26182 | E22: =26000*(1+0.007)^2 -> 26365.274 | F22: =26000*(1+0.007)^3 -> 26549.831 | G22: =26000*(1+0.007)^4 -> 26735.68 | H22: =26000*(1+0.007)^5 -> 26922.829 | I22: =26000*(1+0.007)^6 -> 27111.289 | J22: =26000*(1+0.007)^7 -> 27301.068 | K22: =26000*(1+0.007)^8 -> 27492.176 | L22: =26000*(1+0.007)^9 -> 27684.621 | M22: =26000*(1+0.007)^10 -> 27878.413 | N22: =26000*(1+0.007)^11 -> 28073.562 | O22: =26000*(1+0.007)^12 -> 28270.077 | P22: =26000*(1+0.007)^13 -> 28467.968 | Q22: =26000*(1+0.007)^14 -> 28667.244 | R22: =26000*(1+0.007)^15 -> 28867.914 | S22: =SUM(C22:H22) -> 158755.61 | T22: =SUM(I22:M22) -> 137467.57 | U22: =SUM(N22:R22) -> 142346.76
A23: DEMAND-SUPPLY GAP | B23: kt | C23: =C21-C22 -> 0 | D23: =D21-D22 -> 189.3 | E23: =E21-E22 -> 387.7355 | F23: =F21-F22 -> 595.64848 | G23: =G21-G22 -> 813.39352 | H23: =H21-H22 -> 1041.3383 | I23: =I21-I22 -> 1279.864 | J23: =J21-J22 -> 1529.366 | ... R23: =R21-R22 -> 3973.0521 | S23: =SUM(C23:H23) -> 3027.4158 | T23: =SUM(I23:M23) -> 9010.3436 | U23: =SUM(N23:R23) -> 16475.593
A24: Argentina Supply | B24: kt | C24: =ARGENTINA_SUPPLY!C14 -> 35 | D24: =ARGENTINA_SUPPLY!D14 -> 52 | E24: =ARGENTINA_SUPPLY!E14 -> 69 | F24: =ARGENTINA_SUPPLY!F14 -> 68 | G24: =ARGENTINA_SUPPLY!G14 -> 67 | H24: =ARGENTINA_SUPPLY!H14 -> 67 | I24: =ARGENTINA_SUPPLY!I14 -> 0 | J24: =ARGENTINA_SUPPLY!J14 -> 0 | ... R24: =ARGENTINA_SUPPLY!R14 -> 0 | S24: =SUM(C24:H24) -> 358 | T24: =SUM(I24:M24) -> 0 | U24: =SUM(N24:R24) -> 0
A25: Remaining Gap after AR | B25: kt | C25: =C23-C24 -> -35 | D25: =D23-D24 -> 137.3 | E25: =E23-E24 -> 318.7355 | F25: =F23-F24 -> 527.64848 | G25: =G23-G24 -> 746.39352 | H25: =H23-H24 -> 974.33829 | I25: =I23-I24 -> 1279.864 | J25: =J23-J24 -> 1529.366 | ... R25: =R23-R24 -> 3973.0521 | S25: =SUM(C25:H25) -> 2669.4158 | T25: =SUM(I25:M25) -> 9010.3436 | U25: =SUM(N25:R25) -> 16475.593
A26: Argentina Market Share | B26: % | C26: =IF(C21>0,C24/C21,0) -> 0.0013461538 | D26: =IF(D21>0,D24/D21,0) -> 0.0019718406 | E26: =IF(E21>0,E24/E21,0) -> 0.0025791491 | F26: =IF(F21>0,F24/F21,0) -> 0.0025050211 | G26: =IF(G21>0,G24/G21,0) -> 0.0024320237 | H26: =IF(H21>0,H24/H21,0) -> 0.0023959233 | I26: =IF(I21>0,I24/I21,0) -> 0 | J26: =IF(J21>0,J24/J21,0) -> 0 | ... R26: =IF(R21>0,R24/R21,0) -> 0 | S26: =SUM(C26:H26) -> 0.013230112 | T26: =SUM(I26:M26) -> 0 | U26: =SUM(N26:R26) -> 0
A28: * Global supply modelled as 2025 baseline × (1+CAGR)^n. CAGR assumptions: HIGH=2.0%, REALISTIC=1.4%, LOW=0.7% p.a. Positive Gap = demand exceeds supply (structural deficit); Argentina Market Share = Argentina production / Global demand.

Sheet AR_OPPORTUNITY
A1: ARGENTINA MARKET OPPORTUNITY — Revenue, CAPEX & Economic Impact (USD millions)
A2: Revenue = Argentina production (kt) × LT price (USD/t, from PARAMETERS) × 1,000. CAPEX from PARAMETERS benchmarks applied to new capacity additions. Green cells reference ARGENTINA_SUPPLY and PARAMETERS sheets.
A3: Line Item | B3: Scenario | C3: 2025 | D3: 2026 | E3: 2027 | F3: 2028 | G3: 2029 | H3: 2030 | I3: 2031 | J3: 2032 | K3: 2033 | L3: 2034 | M3: 2035 | N3: 2036 | O3: 2037 | P3: 2038 | Q3: 2039 | R3: 2040 | S3: 5Y Total 2025-30 ($M) | T3: 5Y Total 2031-35 ($M) | U3: 5Y Total 2036-40 ($M) | V3: 15Y Total 2025-40 ($M)
A4: ANNUAL REVENUE ESTIMATES (USD millions)
A5: Revenue (Conservative / Low Price) | C5: =(ARGENTINA_SUPPLY!C14*(PARAMETERS!$B$51*(1-0)+PARAMETERS!$C$51*0))/1000 -> 273 | D5: =(ARGENTINA_SUPPLY!D14*(PARAMETERS!$B$51*(1-0.2)+PARAMETERS!$C$51*0.2))/1000 -> 402.48 | E5: =(ARGENTINA_SUPPLY!E14*(PARAMETERS!$B$51*(1-0.4)+PARAMETERS!$C$51*0.4))/1000 -> 529.92 | F5: =(ARGENTINA_SUPPLY!F14*(PARAMETERS!$B$51*(1-0.6)+PARAMETERS!$C$51*0.6))/1000 -> 518.16 | G5: =(ARGENTINA_SUPPLY!G14*(PARAMETERS!$B$51*(1-0.8)+PARAMETERS!$C$51*0.8))/1000 -> 506.52 | H5: =(ARGENTINA_SUPPLY!H14*(PARAMETERS!$B$51*(1-1)+PARAMETERS!$C$51*1))/1000 -> 502.5 | I5: =(ARGENTINA_SUPPLY!I14*(PARAMETERS!$C$51*(1-0.2)+PARAMETERS!$D$51*0.2))/1000 -> 0 | J5: =(ARGENTINA_SUPPLY!J14*(PARAMETERS!$C$51*(1-0.4)+PARAMETERS!$D$51*0.4))/1000 -> 0 | K5: =(ARGENTINA_SUPPLY!K14*(PARAMETERS!$C$51*(1-0.6)+PARAMETERS!$D$51*0.6))/1000 -> 0 | L5: =(ARGENTINA_SUPPLY!L14*(PARAMETERS!$C$51*(1-0.8)+PARAMETERS!$D$51*0.8))/1000 -> 0 | M5: =(ARGENTINA_SUPPLY!M14*(PARAMETERS!$C$51*(1-1)+PARAMETERS!$D$51*1))/1000 -> 0 | N5: =(ARGENTINA_SUPPLY!N14*(PARAMETERS!$D$51*(1-0.2)+PARAMETERS!$E$51*0.2))/1000 -> 0 | O5: =(ARGENTINA_SUPPLY!O14*(PARAMETERS!$D$51*(1-0.4)+PARAMETERS!$E$51*0.4))/1000 -> 0 | P5: =(ARGENTINA_SUPPLY!P14*(PARAMETERS!$D$51*(1-0.6)+PARAMETERS!$E$51*0.6))/1000 -> 0 | Q5: =(ARGENTINA_SUPPLY!Q14*(PARAMETERS!$D$51*(1-0.8)+PARAMETERS!$E$51*0.8))/1000 -> 0 | R5: =(ARGENTINA_SUPPLY!R14*(PARAMETERS!$D$51*(1-1)+PARAMETERS!$E$51*1))/1000 -> 0 | S5: =SUM(C5:H5) -> 2732.58 | T5: =SUM(I5:M5) -> 0 | U5: =SUM(N5:R5) -> 0 | V5: =SUM(C5:R5) -> 2732.58
A6: Revenue (Base / Realistic Price) | C6: =(ARGENTINA_SUPPLY!C25*(PARAMETERS!$B$50*(1-0)+PARAMETERS!$C$50*0))/1000 -> 322 | D6: =(ARGENTINA_SUPPLY!D25*(PARAMETERS!$B$50*(1-0.2)+PARAMETERS!$C$50*0.2))/1000 -> 484.64 | E6: =(ARGENTINA_SUPPLY!E25*(PARAMETERS!$B$50*(1-0.4)+PARAMETERS!$C$50*0.4))/1000 -> 651.36 | F6: =(ARGENTINA_SUPPLY!F25*(PARAMETERS!$B$50*(1-0.6)+PARAMETERS!$C$50*0.6))/1000 -> 650.08 | G6: =(ARGENTINA_SUPPLY!G25*(PARAMETERS!$B$50*(1-0.8)+PARAMETERS!$C$50*0.8))/1000 -> 1616.56 | H6: =(ARGENTINA_SUPPLY!H25*(PARAMETERS!$B$50*(1-1)+PARAMETERS!$C$50*1))/1000 -> 2126.6 | I6: =(ARGENTINA_SUPPLY!I25*(PARAMETERS!$C$50*(1-0.2)+PARAMETERS!$D$50*0.2))/1000 -> 2717 | J6: =(ARGENTINA_SUPPLY!J25*(PARAMETERS!$C$50*(1-0.4)+PARAMETERS!$D$50*0.4))/1000 -> 3107.52 | K6: =(ARGENTINA_SUPPLY!K25*(PARAMETERS!$C$50*(1-0.6)+PARAMETERS!$D$50*0.6))/1000 -> 3514 | L6: =(ARGENTINA_SUPPLY!L25*(PARAMETERS!$C$50*(1-0.8)+PARAMETERS!$D$50*0.8))/1000 -> 3542 | M6: =(ARGENTINA_SUPPLY!M25*(PARAMETERS!$C$50*(1-1)+PARAMETERS!$D$50*1))/1000 -> 3570 | N6: =(ARGENTINA_SUPPLY!N25*(PARAMETERS!$D$50*(1-0.2)+PARAMETERS!$E$50*0.2))/1000 -> 3591 | O6: =(ARGENTINA_SUPPLY!O25*(PARAMETERS!$D$50*(1-0.4)+PARAMETERS!$E$50*0.4))/1000 -> 3612 | P6: =(ARGENTINA_SUPPLY!P25*(PARAMETERS!$D$50*(1-0.6)+PARAMETERS!$E$50*0.6))/1000 -> 3633 | Q6: =(ARGENTINA_SUPPLY!Q25*(PARAMETERS!$D$50*(1-0.8)+PARAMETERS!$E$50*0.8))/1000 -> 3654 | R6: =(ARGENTINA_SUPPLY!R25*(PARAMETERS!$D$50*(1-1)+PARAMETERS!$E$50*1))/1000 -> 3675 | S6: =SUM(C6:H6) -> 5851.24 | T6: =SUM(I6:M6) -> 16450.52 | U6: =SUM(N6:R6) -> 18165 | V6: =SUM(C6:R6) -> 40466.76
A7: Revenue (Maximum / High Price) | C7: =(ARGENTINA_SUPPLY!C36*(PARAMETERS!$B$49*(1-0)+PARAMETERS!$C$49*0))/1000 -> 367.5 | D7: =(ARGENTINA_SUPPLY!D36*(PARAMETERS!$B$49*(1-0.2)+PARAMETERS!$C$49*0.2))/1000 -> 561.6 | E7: =(ARGENTINA_SUPPLY!E36*(PARAMETERS!$B$49*(1-0.4)+PARAMETERS!$C$49*0.4))/1000 -> 765.9 | F7: =(ARGENTINA_SUPPLY!F36*(PARAMETERS!$B$49*(1-0.6)+PARAMETERS!$C$49*0.6))/1000 -> 775.2 | G7: =(ARGENTINA_SUPPLY!G36*(PARAMETERS!$B$49*(1-0.8)+PARAMETERS!$C$49*0.8))/1000 -> 1953.9 | H7: =(ARGENTINA_SUPPLY!H36*(PARAMETERS!$B$49*(1-1)+PARAMETERS!$C$49*1))/1000 -> 2604 | I7: =(ARGENTINA_SUPPLY!I36*(PARAMETERS!$C$49*(1-0.2)+PARAMETERS!$D$49*0.2))/1000 -> 3355 | J7: =(ARGENTINA_SUPPLY!J36*(PARAMETERS!$C$49*(1-0.4)+PARAMETERS!$D$49*0.4))/1000 -> 5108.8 | K7: =(ARGENTINA_SUPPLY!K36*(PARAMETERS!$C$49*(1-0.6)+PARAMETERS!$D$49*0.6))/1000 -> 8631 | L7: =(ARGENTINA_SUPPLY!L36*(PARAMETERS!$C$49*(1-0.8)+PARAMETERS!$D$49*0.8))/1000 -> 11046.4 | M7: =(ARGENTINA_SUPPLY!M36*(PARAMETERS!$C$49*(1-1)+PARAMETERS!$D$49*1))/1000 -> 13286 | N7: =(ARGENTINA_SUPPLY!N36*(PARAMETERS!$D$49*(1-0.2)+PARAMETERS!$E$49*0.2))/1000 -> 14058 | O7: =(ARGENTINA_SUPPLY!O36*(PARAMETERS!$D$49*(1-0.4)+PARAMETERS!$E$49*0.4))/1000 -> 14606 | P7: =(ARGENTINA_SUPPLY!P36*(PARAMETERS!$D$49*(1-0.6)+PARAMETERS!$E$49*0.6))/1000 -> 14824 | Q7: =(ARGENTINA_SUPPLY!Q36*(PARAMETERS!$D$49*(1-0.8)+PARAMETERS!$E$49*0.8))/1000 -> 15042 | R7: =(ARGENTINA_SUPPLY!R36*(PARAMETERS!$D$49*(1-1)+PARAMETERS!$E$49*1))/1000 -> 15260 | S7: =SUM(C7:H7) -> 7028.1 | T7: =SUM(I7:M7) -> 41427.2 | U7: =SUM(N7:R7) -> 73790 | V7: =SUM(C7:R7) -> 122245.3
A9: CAPEX REQUIREMENTS (USD millions)
A10: Project CAPEX Phasing (Base Scenario) | C10: Spend phased over 4 years before start of production.
A11: Project | B11: Type | C11: 2025 | D11: 2026 | E11: 2027 | F11: 2028 | G11: 2029 | H11: 2030 | I11: 2031 | J11: 2032 | K11: 2033 | L11: 2034 | M11: 2035 | N11: 2036 | O11: 2037 | P11: 2038 | Q11: 2039 | R11: 2040 | S11: Total CAPEX ($M)
A12: MARA (Agua Rica) | B12: Greenfield | C12: =(200*1000*PARAMETERS!$B$55/1000000)/4 -> 1000 | D12: 0 | E12: 0 | F12: 0 | G12: 0 | H12: 0 | I12: 0 | J12: 0 | K12: 0 | L12: 0 | M12: 0 | N12: 0 | O12: 0 | P12: 0 | Q12: 0 | R12: 0 | S12: =SUM(C12:R12) -> 1000
A13: Josemaría | B13: Greenfield | C13: =(150*1000*PARAMETERS!$B$55/1000000)/4 -> 750 | D13: =(150*1000*PARAMETERS!$B$55/1000000)/4 -> 750 | E13: 0 | F13: 0 | G13: 0 | H13: 0 | I13: 0 | J13: 0 | K13: 0 | L13: 0 | M13: 0 | N13: 0 | O13: 0 | P13: 0 | Q13: 0 | R13: 0 | S13: =SUM(C13:R13) -> 1500
A14: El Pachón | B14: Greenfield | C14: =(200*1000*PARAMETERS!$B$55/1000000)/4 -> 1000 | D14: =(200*1000*PARAMETERS!$B$55/1000000)/4 -> 1000 | E14: =(200*1000*PARAMETERS!$B$55/1000000)/4 -> 1000 | F14: 0 | G14: 0 | H14: 0 | I14: 0 | J14: 0 | K14: 0 | L14: 0 | M14: 0 | N14: 0 | O14: 0 | P14: 0 | Q14: 0 | R14: 0 | S14: =SUM(C14:R14) -> 3000
A15: Los Azules | B15: Greenfield | C15: =(200*1000*PARAMETERS!$B$55/1000000)/4 -> 1000 | D15: =(200*1000*PARAMETERS!$B$55/1000000)/4 -> 1000 | E15: =(200*1000*PARAMETERS!$B$55/1000000)/4 -> 1000 | F15: =(200*1000*PARAMETERS!$B$55/1000000)/4 -> 1000 | G15: 0 | H15: 0 | I15: 0 | J15: 0 | K15: 0 | L15: 0 | M15: 0 | N15: 0 | O15: 0 | P15: 0 | Q15: 0 | R15: 0 | S15: =SUM(C15:R15) -> 4000
A16: Taca Taca | B16: Greenfield | C16: 0 | D16: =(170*1000*PARAMETERS!$B$55/1000000)/4 -> 850 | E16: =(170*1000*PARAMETERS!$B$55/1000000)/4 -> 850 | F16: =(170*1000*PARAMETERS!$B$55/1000000)/4 -> 850 | G16: =(170*1000*PARAMETERS!$B$55/1000000)/4 -> 850 | H16: 0 | I16: 0 | J16: 0 | K16: 0 | L16: 0 | M16: 0 | N16: 0 | O16: 0 | P16: 0 | Q16: 0 | R16: 0 | S16: =SUM(C16:R16) -> 3400
A17: Altar | B17: Greenfield | C17: 0 | D17: 0 | E17: =(100*1000*PARAMETERS!$B$55/1000000)/4 -> 500 | F17: =(100*1000*PARAMETERS!$B$55/1000000)/4 -> 500 | G17: =(100*1000*PARAMETERS!$B$55/1000000)/4 -> 500 | H17: =(100*1000*PARAMETERS!$B$55/1000000)/4 -> 500 | I17: 0 | J17: 0 | K17: 0 | L17: 0 | M17: 0 | N17: 0 | O17: 0 | P17: 0 | Q17: 0 | R17: 0 | S17: =SUM(C17:R17) -> 2000
A18: San Jorge | B18: Brownfield | C18: 0 | D18: 0 | E18: 0 | F18: =(70*1000*PARAMETERS!$B$56/1000000)/4 -> 140 | G18: =(70*1000*PARAMETERS!$B$56/1000000)/4 -> 140 | H18: =(70*1000*PARAMETERS!$B$56/1000000)/4 -> 140 | I18: =(70*1000*PARAMETERS!$B$56/1000000)/4 -> 140 | J18: 0 | K18: 0 | L18: 0 | M18: 0 | N18: 0 | O18: 0 | P18: 0 | Q18: 0 | R18: 0 | S18: =SUM(C18:R18) -> 560
A19: TOTAL CAPEX (Base — all projects) | C19: =SUM(C12:C18) -> 3750 | D19: =SUM(D12:D18) -> 3600 | E19: =SUM(E12:E18) -> 3350 | F19: =SUM(F12:F18) -> 2490 | G19: =SUM(G12:G18) -> 1490 | H19: =SUM(H12:H18) -> 640 | I19: =SUM(I12:I18) -> 140 | J19: =SUM(J12:J18) -> 0 | ... R19: =SUM(R12:R18) -> 0 | S19: =SUM(C19:R19) -> 15460
A21: ECONOMIC IMPACT SUMMARY (Base Scenario Estimates)
A22: Direct employment (jobs per kt annual production) | C22: 250 | D22: Benchmark: 200–300 jobs/kt capacity (ICSG)
A23: Indirect employment multiplier | C23: 2.5 | D23: Standard mining sector multiplier
A24: Export revenue share in Argentine GDP (%) | C24: See formula | D24: Calculated from revenue / Argentine GDP (~$700B)
A25: Royalty income to provinces ($ million/year by 2040) | C25: See formula | D25: Formula: Revenue × provincial royalty rate (PARAMETERS!B58)
A26: Federal tax revenue ($ million/year by 2040) | C26: See formula | D26: Formula: EBITDA margin ~45% × CIT rate (PARAMETERS!B62)

Sheet COUNTRY_SCORING
A1: COUNTRY & PROJECT ATTRACTIVENESS SCORING — Argentina vs. Key Competitors (Scale 1–4)
A2: Adapted from EU Copper Sector Analysis (2026) methodology: Total Score = 60% × Business Score + 40% × Country Score. Scale: 1=Poor, 2=Below Average, 3=Above Average, 4=Excellent.
A4: A. BUSINESS SCORE CRITERIA (Weight = 60% of Total)
A5: Criterion | B5: Weight | C5: Argentina | D5: Chile | E5: Peru | F5: DRC | G5: Canada | H5: Australia | I5: Zambia | J5: Indonesia
A6: Mine capacity (>200 kt = 4) | B6: 0.2 | C6: 3 | D6: 3.5 | E6: 3 | F6: 3.5 | G6: 3.5 | H6: 3.5 | I6: 2.5 | J6: 3
A7: Life of mine (>30 yrs = 4) | B7: 0.15 | C7: 3 | D7: 3.5 | E7: 3 | F7: 3.5 | G7: 3.5 | H7: 3.5 | I7: 2.5 | J7: 2.5
A8: Ore grade (>1.0% = 4) | B8: 0.05 | C8: 2.5 | D8: 3.5 | E8: 3 | F8: 3.5 | G8: 3 | H8: 3 | I8: 2.5 | J8: 2.5
A9: Mine type (OP preferred = 4) | B9: 0.05 | C9: 3.5 | D9: 3.5 | E9: 3 | F9: 3.5 | G9: 3 | H9: 3.5 | I9: 3 | J9: 3.5
A10: Export logistics (port distance) | B10: 0.05 | C10: 3 | D10: 3.5 | E10: 3.5 | F10: 2 | G10: 3.5 | H10: 3.5 | I10: 2 | J10: 3
A11: Access to water | B11: 0.1 | C11: 2 | D11: 2.5 | E11: 2.5 | F11: 3.5 | G11: 3.5 | H11: 3.5 | I11: 3 | J11: 2.5
A12: Access to power / energy cost | B12: 0.05 | C12: 3 | D12: 3 | E12: 2.5 | F12: 2.5 | G12: 3.5 | H12: 3.5 | I12: 2 | J12: 2.5
A13: Available labour skills | B13: 0.05 | C13: 3 | D13: 3.5 | E13: 3 | F13: 2.5 | G13: 3.5 | H13: 3.5 | I13: 2.5 | J13: 2.5
A14: Exploitation permit availability | B14: 0.1 | C14: 3 | D14: 3.5 | E14: 3 | F14: 2.5 | G14: 3.5 | H14: 4 | I14: 2.5 | J14: 2.5
A15: Environmental permitting | B15: 0.1 | C15: 2.5 | D15: 3 | E15: 2.5 | F15: 2.5 | G15: 3.5 | H15: 4 | I15: 2 | J15: 2.5
A16: Relation with local communities | B16: 0.1 | C16: 2.5 | D16: 3 | E16: 2.5 | F16: 2 | G16: 3.5 | H16: 3.5 | I16: 2.5 | J16: 2.5
A17: WEIGHTED BUSINESS SCORE | C17: =SUMPRODUCT($B$6:$B$16,C6:C16)/SUM($B$6:$B$16) -> 2.8 | D17: =SUMPRODUCT($B$6:$B$16,D6:D16)/SUM($B$6:$B$16) -> 3.275 | E17: =SUMPRODUCT($B$6:$B$16,E6:E16)/SUM($B$6:$B$16) -> 2.85 | F17: =SUMPRODUCT($B$6:$B$16,F6:F16)/SUM($B$6:$B$16) -> 2.975 | G17: =SUMPRODUCT($B$6:$B$16,G6:G16)/SUM($B$6:$B$16) -> 3.45 | H17: =SUMPRODUCT($B$6:$B$16,H6:H16)/SUM($B$6:$B$16) -> 3.575 | I17: =SUMPRODUCT($B$6:$B$16,I6:I16)/SUM($B$6:$B$16) -> 2.475 | J17: =SUMPRODUCT($B$6:$B$16,J6:J16)/SUM($B$6:$B$16) -> 2.675
A19: B. COUNTRY SCORE CRITERIA (Weight = 40% of Total)
A20: Criterion | B20: Weight | C20: Argentina | D20: Chile | E20: Peru | F20: DRC | G20: Canada | H20: Australia | I20: Zambia | J20: Indonesia
A21: Political stability (Global Peace Index + GINI + CPI) | B21: 0.4 | C21: 2.5 | D21: 3.5 | E21: 2.5 | F21: 1.5 | G21: 4 | H21: 4 | I21: 2 | J21: 2.5
A22: Mining licence regime & duration | B22: 0.15 | C22: 3 | D22: 3.5 | E22: 3 | F22: 2 | G22: 4 | H22: 4 | I22: 2.5 | J22: 2.5
A23: State participation & fiscal regime | B23: 0.15 | C23: 3 | D23: 3 | E23: 2.5 | F23: 2 | G23: 3.5 | H23: 3.5 | I23: 2.5 | J23: 2.5
A24: Environmental & social framework | B24: 0.1 | C24: 2.5 | D24: 3 | E24: 2.5 | F24: 2 | G24: 4 | H24: 4 | I24: 2 | J24: 2.5
A25: Trade freedom & currency convertibility | B25: 0.1 | C25: 2.5 | D25: 3.5 | E25: 3 | F25: 2.5 | G25: 4 | H25: 4 | I25: 2.5 | J25: 2.5
A26: Dispute resolution & investment protection | B26: 0.1 | C26: 2.5 | D26: 3.5 | E26: 2.5 | F26: 2 | G26: 4 | H26: 4 | I26: 2 | J26: 2
A27: WEIGHTED COUNTRY SCORE | C27: =SUMPRODUCT($B$21:$B$26,C21:C26)/SUM($B$21:$B$26) -> 2.65 | D27: =SUMPRODUCT($B$21:$B$26,D21:D26)/SUM($B$21:$B$26) -> 3.375 | E27: =SUMPRODUCT($B$21:$B$26,E21:E26)/SUM($B$21:$B$26) -> 2.625 | F27: =SUMPRODUCT($B$21:$B$26,F21:F26)/SUM($B$21:$B$26) -> 1.85 | G27: =SUMPRODUCT($B$21:$B$26,G21:G26)/SUM($B$21:$B$26) -> 3.925 | H27: =SUMPRODUCT($B$21:$B$26,H21:H26)/SUM($B$21:$B$26) -> 3.925 | I27: =SUMPRODUCT($B$21:$B$26,I21:I26)/SUM($B$21:$B$26) -> 2.2 | J27: =SUMPRODUCT($B$21:$B$26,J21:J26)/SUM($B$21:$B$26) -> 2.45
A29: COMPOSITE SCORE (60% Business + 40% Country) | C29: =0.6*C17+0.4*C27 -> 2.74 | D29: =0.6*D17+0.4*D27 -> 3.315 | E29: =0.6*E17+0.4*E27 -> 2.76 | F29: =0.6*F17+0.4*F27 -> 2.525 | G29: =0.6*G17+0.4*G27 -> 3.64 | H29: =0.6*H17+0.4*H27 -> 3.715 | I29: =0.6*I17+0.4*I27 -> 2.365 | J29: =0.6*J17+0.4*J27 -> 2.585
A30: RANKING (1 = Most Attractive) | C30: =RANK(C29,C29:J29,0) -> 5 | D30: =RANK(D29,C29:J29,0) -> 3 | E30: =RANK(E29,C29:J29,0) -> 4 | F30: =RANK(F29,C29:J29,0) -> 7 | G30: =RANK(G29,C29:J29,0) -> 2 | H30: =RANK(H29,C29:J29,0) -> 1 | I30: =RANK(I29,C29:J29,0) -> 8 | J30: =RANK(J29,C29:J29,0) -> 6
A32: ARGENTINA IMPROVEMENT LEVERS: Key areas where policy reforms can improve scores: (1) Mining licence certainty & reduction of administrative discretion → +0.5 Country Score; (2) Currency convertibility & profit repatriation guarantees → +0.5; (3) Environmental permitting streamlining → +0.3; (4) Local community frameworks (benefit-sharing mechanisms) → +0.3. Combined effect: Argentina Composite Score could improve from ~2.7 to ~3.1, narrowing the gap with Chile (3.3) significantly.

Sheet PATHWAYS
A1: STRATEGIC PATHWAYS — Three Courses of Action for Argentina's Mining Sector (2025–2040)
A3: Metric / Line Item | B3: Units | C3: 2025 | D3: 2026 | E3: 2027 | F3: 2028 | G3: 2029 | H3: 2030 | I3: 2031 | J3: 2032 | K3: 2033 | L3: 2034 | M3: 2035 | N3: 2036 | O3: 2037 | P3: 2038 | Q3: 2039 | R3: 2040
A4: PATHWAY 1 — STATUS QUO (No new investment beyond committed projects)
A5: Conservative supply, Realistic demand. Relies on existing and committed operations only. No new project development, no value-added processing investment.
A6: Production scenario | B6: Conservative | J6: Domestic value capture | K6: ~20% of LME price
A7: Value chain position | B7: Mining only (concentrate exports) | J7: Estimated 15Y revenue ($B) | K7: ~45–55
A8: New smelting investment | B8: None | J8: CAPEX required ($B) | K8: ~8–10 (mining only)
A9: New refining investment | B9: None | J9: Employment created | K9: ~15,000 direct
A10: Export product form | B10: Copper concentrates (Cu ~30%) | J10: Strategic dependency risk | K10: High (price taker, single commodity)
A12: Annual Production and Revenue Profile
A13: Argentina Production (kt) | C13: =ARGENTINA_SUPPLY!C14 -> 35 | D13: =ARGENTINA_SUPPLY!D14 -> 52 | E13: =ARGENTINA_SUPPLY!E14 -> 69 | F13: =ARGENTINA_SUPPLY!F14 -> 68 | G13: =ARGENTINA_SUPPLY!G14 -> 67 | H13: =ARGENTINA_SUPPLY!H14 -> 67 | I13: =ARGENTINA_SUPPLY!I14 -> 0 | J13: =ARGENTINA_SUPPLY!J14 -> 0 | ... R13: =ARGENTINA_SUPPLY!R14 -> 0
A14: LME Price Assumption ($/t) | C14: =(PARAMETERS!$B$51*(1-0)+PARAMETERS!$C$51*0) -> 7800 | D14: =(PARAMETERS!$B$51*(1-0.2)+PARAMETERS!$C$51*0.2) -> 7740 | E14: =(PARAMETERS!$B$51*(1-0.4)+PARAMETERS!$C$51*0.4) -> 7680 | F14: =(PARAMETERS!$B$51*(1-0.6)+PARAMETERS!$C$51*0.6) -> 7620 | G14: =(PARAMETERS!$B$51*(1-0.8)+PARAMETERS!$C$51*0.8) -> 7560 | H14: =(PARAMETERS!$B$51*(1-1)+PARAMETERS!$C$51*1) -> 7500 | I14: =(PARAMETERS!$C$51*(1-0.2)+PARAMETERS!$D$51*0.2) -> 7440 | J14: =(PARAMETERS!$C$51*(1-0.4)+PARAMETERS!$D$51*0.4) -> 7380 | K14: =(PARAMETERS!$C$51*(1-0.6)+PARAMETERS!$D$51*0.6) -> 7320 | L14: =(PARAMETERS!$C$51*(1-0.8)+PARAMETERS!$D$51*0.8) -> 7260 | M14: =(PARAMETERS!$C$51*(1-1)+PARAMETERS!$D$51*1) -> 7200 | N14: =(PARAMETERS!$D$51*(1-0.2)+PARAMETERS!$E$51*0.2) -> 7160 | O14: =(PARAMETERS!$D$51*(1-0.4)+PARAMETERS!$E$51*0.4) -> 7120 | P14: =(PARAMETERS!$D$51*(1-0.6)+PARAMETERS!$E$51*0.6) -> 7080 | Q14: =(PARAMETERS!$D$51*(1-0.8)+PARAMETERS!$E$51*0.8) -> 7040 | R14: =(PARAMETERS!$D$51*(1-1)+PARAMETERS!$E$51*1) -> 7000
A15: Annual Revenue ($M) | C15: =(C13*C14)/1000 -> 273 | D15: =(D13*D14)/1000 -> 402.48 | E15: =(E13*E14)/1000 -> 529.92 | F15: =(F13*F14)/1000 -> 518.16 | G15: =(G13*G14)/1000 -> 506.52 | H15: =(H13*H14)/1000 -> 502.5 | I15: =(I13*I14)/1000 -> 0 | J15: =(J13*J14)/1000 -> 0 | ... R15: =(R13*R14)/1000 -> 0
